Traceback (most recent call last):
  File "manage.py", line 22, in <module>
    main()
  File "manage.py", line 18, in main
    execute_from_command_line(sys.argv)
  File "/root/with-fit/venv/lib/python3.6/site-packages/django/core/management/__init__.py", line 419, in execute_from_command_line
    utility.execute()
  File "/root/with-fit/venv/lib/python3.6/site-packages/django/core/management/__init__.py", line 363, in execute
    settings.INSTALLED_APPS
  File "/root/with-fit/venv/lib/python3.6/site-packages/django/conf/__init__.py", line 82, in __getattr__
    self._setup(name)
  File "/root/with-fit/venv/lib/python3.6/site-packages/django/conf/__init__.py", line 69, in _setup
    self._wrapped = Settings(settings_module)
  File "/root/with-fit/venv/lib/python3.6/site-packages/django/conf/__init__.py", line 170, in __init__
    mod = importlib.import_module(self.SETTINGS_MODULE)
  File "/usr/lib/python3.6/importlib/__init__.py", line 126, in import_module
    return _bootstrap._gcd_import(name[level:], package, level)
  File "<frozen importlib._bootstrap>", line 994, in _gcd_import
  File "<frozen importlib._bootstrap>", line 971, in _find_and_load
  File "<frozen importlib._bootstrap>", line 955, in _find_and_load_unlocked
  File "<frozen importlib._bootstrap>", line 665, in _load_unlocked
  File "<frozen importlib._bootstrap_external>", line 678, in exec_module
  File "<frozen importlib._bootstrap>", line 219, in _call_with_frames_removed
  File "/root/with-fit/config/settings.py", line 146, in <module>
    STATIC_ROOT = os.path.join(BASE_DIR, 'static/')
NameError: name 'os' is not defined
